Workbook

Sheet Summary
A1: 美博工程服務有限公司
A2: MS_Q1241_24_kp (MTR C9644-24C Extension of Fitness Room at KBD Recreation & Sports Centre)
A4: (Project No. MS_Q1241_24)
A5: 地盤糧期狀況
A6: 工期 | B6: 12/2024 - 01/2026 | C6: (390天)
A8: 總承建商(MC): | B8: Mepork Engineering Service Limited
A9: 承包商(SUB-CON):
A10: 承包商(SUB-CON):
A13: 承建金額: | B13: 7400000
A14: (a) | C14: Option 1
A15: (b) | C15: Option 2
A16: (c)
A17: (d)
A18: (A) Sub-total: | B18: =SUM(B13:B17) -> 7400000
A21: 承包商(SUB-CON): | B21: 宏發工程公司
A22: (a) | B22: ='Project Summary'!J13 -> 1900000 | C22: Builder's Works | D22: 宏發建築工程公司 | E22: SC-003
A23: (b) | B23: ='Project Summary'!J11 -> 800000 | C23: FS | D23: 大同工程有限公司 | E23: SC-002
A24: (c) | B24: ='Project Summary'!J26+'Project Summary'!J27 -> 1212880 | C24: EL Labour | D24: 照明工程有限公司 | E24: SC-010 & SC-010.1
A25: (d) | B25: ='Project Summary'!J16 -> 800000 | C25: ECS | D25: 盈泊工程公司 | E25: SC-004
A26: (e) | B26: ='Project Summary'!J23+'Project Summary'!J24 -> 15500 | C26: Design of Hoarding, SE | D26: 華文工程有限公司 | E26: SC-008 & SC-008.1
A27: (f)
A30: (B) Sub-total: | B30: =SUM(B22:B29) -> 4728380
A32: (C) = (A) - (B) 利潤: | B32: =B18-B30 -> 2671620
A33: Less Expenses : | B33: ='Project Summary'!J9 -> 44360 | C33: Insurance - EC | D33: 恒傑保險業務有限公司 | E33: O-001
A34: Less Expenses : | B34: ='Project Summary'!J14 -> 15000 | C34: Q167/21 搭架比EMSD驗收燈柱 | D34: 宏發建築工程公司 | E34: SC-003A
A35: Less Expenses : | B35: ='Project Summary'!J17 -> 83000 | C35: 代買冷氣機 | D35: 盈泊工程公司 | E35: SC-004A
A36: Less Expenses : | B36: ='Project Summary'!J18 -> 27242.5 | C36: Levies | D36: 環境保護署 | E36: O-005
A37: Less Expenses : | B37: ='Project Summary'!J19+'Project Summary'!J21 -> 284000 | C37: Safety | D37: 滅火筒安全顧問 | E37: O-006 & O-006.1
A38: Less Expenses : | B38: ='Project Summary'!J22 -> 2000 | C38: CP Training | D38: MTR | E38: O-007
A39: Less Expenses : | B39: ='Project Summary'!J59 -> 14006 | C39: Levies | D39: 建造業議會 | E39: O-012
A40: Less Expenses : | B40: ='Project Summary'!J60 -> 12038.9 | C40: Miscellaneous | E40: O-013
A41: Less Expenses : | B41: ='Project Summary'!J61 -> 6279 | C41: Levies | D41: 肺塵埃沉着病補償基金委員會 | E41: O-014
A42: Less Expenses : | B42: ='Project Summary'!J25 -> 1640 | C42: Body Check | D42: 聯康醫療 | E42: O-009
A43: Less Expenses : | B43: ='Project Summary'!J62 -> 174600 | C43: Light fitting | D43: ALCO LIGHTING (H.K.) LTD | E43: M-015
A44: Less Expenses : | B44: =SUM('Project Summary'!J28:J46) -> 187121.1 | C44: EL - Material | D44: 信成電器材料有限公司 | E44: M-011.1 - M-011.19
A45: Less Expenses :
A46: Less Expenses :
A47: Less Expenses :
A48: Less Expenses :
A49: Less Expenses :
...

Sheet 代支工程, 物料
A1: =Summary!A2 -> MS_Q1241_24_kp (MTR C9644-24C Extension of Fitness Room at KBD Recreation & Sports Centre)
A2: 代支工程總表
A3: Updated on 12/12/2024
A4: No. | B4: Link | C4: Invoice Date | D4: Invoice No. | E4: Quotation No. | F4: Sub-contractors' No | G4: Company Name | H4: Company Name (in Chinese) | I4: Description | J4: Contract Amount (HK$) | K4: Paid Amount (HK$) | L4: Remainder Amount (HK$) | M4: OA日期 | N4: OA編號 | O4: MC IP-No. | P4: B/C to sub-contractor | Q4: Sub-IP No. | R4: Reamrk
A5: 1 | B5: =HYPERLINK("Z:\MePork\000 綜合\020 報價合約\Quotation\2024\MS_Q1241_24_kp (C9644-24C Extension of Fitness Room at KBD Recreation & Sports Centre)\P1 - Payment\Payment records\"&A5&".PDF",A5) -> 1 | C5: 45637 | D5: I0482530 | F5: O-001 | G5: =IFERROR(VLOOKUP($F5,'Project Summary'!$B$9:$M$106,3,FALSE),"") -> REALIFE INSURANCE BROKERS LTD. | H5: =IFERROR(VLOOKUP($F5,'Project Summary'!$B$9:$M$106,4,FALSE),"") -> 恒傑保險業務有限公司 | I5: =IFERROR(VLOOKUP($F5,'Project Summary'!$B$9:$M$106,5,FALSE),"") -> Insurance - EC | J5: =IFERROR(VLOOKUP($F5,'Project Summary'!$B$9:$M$106,7,FALSE),"") -> 44360 | K5: 44360 | L5: =IFERROR(J5-K5,"") -> 0 | R5: Pokfulam No. 599 Transfer to WCH No.1 | S5: =HYPERLINK("Q:\Project No. 016A - HKSR PHI Renovation at Pokfulam\P1 - Payment\Payment Records\"&A5&".PDF",A5)
A6: 2 | B6: =HYPERLINK("Z:\MePork\000 綜合\020 報價合約\Quotation\2024\MS_Q1241_24_kp (C9644-24C Extension of Fitness Room at KBD Recreation & Sports Centre)\P1 - Payment\Payment records\"&A6&".PDF",A6) -> 2 | C6: 45645 | D6: Q-CEL-FS-2411-01 | F6: SC-002 | G6: =IFERROR(VLOOKUP($F6,'Project Summary'!$B$9:$M$106,3,FALSE),"") -> CHASE ENGINEERING LIMITED | H6: =IFERROR(VLOOKUP($F6,'Project Summary'!$B$9:$M$106,4,FALSE),"") -> 大同工程有限公司 | I6: =IFERROR(VLOOKUP($F6,'Project Summary'!$B$9:$M$106,5,FALSE),"") -> Fire Services Installation | J6: =IFERROR(VLOOKUP($F6,'Project Summary'!$B$9:$M$106,7,FALSE),"") -> 800000 | K6: 100000 | L6: =IFERROR(J6-K6,"") -> 700000
A7: 3 | B7: =HYPERLINK("Z:\MePork\000 綜合\020 報價合約\Quotation\2024\MS_Q1241_24_kp (C9644-24C Extension of Fitness Room at KBD Recreation & Sports Centre)\P1 - Payment\Payment records\"&A7&".PDF",A7) -> 3 | C7: 45646 | F7: SC-003 | G7: =IFERROR(VLOOKUP($F7,'Project Summary'!$B$9:$M$106,3,FALSE),"") -> WANG FAT CONSTRUCTION CO. | H7: =IFERROR(VLOOKUP($F7,'Project Summary'!$B$9:$M$106,4,FALSE),"") -> 宏發建築工程公司 | I7: =IFERROR(VLOOKUP($F7,'Project Summary'!$B$9:$M$106,5,FALSE),"") -> Builder's Works | J7: =IFERROR(VLOOKUP($F7,'Project Summary'!$B$9:$M$106,7,FALSE),"") -> 1900000 | K7: 200000 | L7: =IFERROR(J7-K7,"") -> 1700000
A8: 4 | B8: =HYPERLINK("Z:\MePork\000 綜合\020 報價合約\Quotation\2024\MS_Q1241_24_kp (C9644-24C Extension of Fitness Room at KBD Recreation & Sports Centre)\P1 - Payment\Payment records\"&A8&".PDF",A8) -> 4 | C8: 45642 | D8: 12024180 | F8: SC-004 | G8: =IFERROR(VLOOKUP($F8,'Project Summary'!$B$9:$M$106,3,FALSE),"") -> YING PAK ENGINEERING COMPANY | H8: =IFERROR(VLOOKUP($F8,'Project Summary'!$B$9:$M$106,4,FALSE),"") -> 盈泊工程公司 | I8: MVAC Installation - IP-01 | J8: =IFERROR(VLOOKUP($F8,'Project Summary'!$B$9:$M$106,7,FALSE),"") -> 800000 | K8: 150000 | L8: =IFERROR(J8-K8,"") -> 650000
A9: 5 | B9: =HYPERLINK("Z:\MePork\000 綜合\020 報價合約\Quotation\2024\MS_Q1241_24_kp (C9644-24C Extension of Fitness Room at KBD Recreation & Sports Centre)\P1 - Payment\Payment records\"&A9&".PDF",A9) -> 5 | C9: 45657 | D9: 705330010 | F9: O-005 | G9: =IFERROR(VLOOKUP($F9,'Project Summary'!$B$9:$M$106,3,FALSE),"") -> Environmental Protection Department | H9: =IFERROR(VLOOKUP($F9,'Project Summary'!$B$9:$M$106,4,FALSE),"") -> 環境保護署 | I9: =IFERROR(VLOOKUP($F9,'Project Summary'!$B$9:$M$106,5,FALSE),"") -> Waste Dispoal | J9: =IFERROR(VLOOKUP($F9,'Project Summary'!$B$9:$M$106,7,FALSE),"") -> 27242.5 | K9: 15000 | L9: =IFERROR(J9-K9,"") -> 12242.5
A10: 6 | B10: =HYPERLINK("Z:\MePork\000 綜合\020 報價合約\Quotation\2024\MS_Q1241_24_kp (C9644-24C Extension of Fitness Room at KBD Recreation & Sports Centre)\P1 - Payment\Payment records\"&A10&".PDF",A10) -> 6 | C10: 45659 | D10: INV2/1/2025 | F10: O-006 | G10: =IFERROR(VLOOKUP($F10,'Project Summary'!$B$9:$M$106,3,FALSE),"") -> FIRE EXTINGUISHER SAFETY CONSULTANT | H10: =IFERROR(VLOOKUP($F10,'Project Summary'!$B$9:$M$106,4,FALSE),"") -> 滅火筒安全顧問 | I10: =IFERROR(VLOOKUP($F10,'Project Summary'!$B$9:$M$106,5,FALSE),"") -> Safety | J10: =IFERROR(VLOOKUP($F10,'Project Summary'!$B$9:$M$106,7,FALSE),"") -> 272000 | K10: 7742 | L10: =IFERROR(J10-K10,"") -> 264258
A11: 7 | B11: =HYPERLINK("Z:\MePork\000 綜合\020 報價合約\Quotation\2024\MS_Q1241_24_kp (C9644-24C Extension of Fitness Room at KBD Recreation & Sports Centre)\P1 - Payment\Payment records\"&A11&".PDF",A11) -> 7 | C11: 25/1/2025 | F11: SC-003 | G11: =IFERROR(VLOOKUP($F11,'Project Summary'!$B$9:$M$106,3,FALSE),"") -> WANG FAT CONSTRUCTION CO. | H11: =IFERROR(VLOOKUP($F11,'Project Summary'!$B$9:$M$106,4,FALSE),"") -> 宏發建築工程公司 | I11: =IFERROR(VLOOKUP($F11,'Project Summary'!$B$9:$M$106,5,FALSE),"") -> Builder's Works | J11: =IFERROR(VLOOKUP($F11,'Project Summary'!$B$9:$M$106,7,FALSE),"") -> 1900000 | K11: 180000 | L11: =IFERROR(J11-K11,"") -> 1720000
A12: 8 | B12: =HYPERLINK("Z:\MePork\000 綜合\020 報價合約\Quotation\2024\MS_Q1241_24_kp (C9644-24C Extension of Fitness Room at KBD Recreation & Sports Centre)\P1 - Payment\Payment records\"&A12&".PDF",A12) -> 8 | C12: 45690 | D12: 102-004363-001 | F12: O-007 | G12: =IFERROR(VLOOKUP($F12,'Project Summary'!$B$9:$M$106,3,FALSE),"") -> MTR | H12: =IFERROR(VLOOKUP($F12,'Project Summary'!$B$9:$M$106,4,FALSE),"") -> 0 | I12: =IFERROR(VLOOKUP($F12,'Project Summary'!$B$9:$M$106,5,FALSE),"") -> CP Training | J12: =IFERROR(VLOOKUP($F12,'Project Summary'!$B$9:$M$106,7,FALSE),"") -> 2000 | K12: 500 | L12: =IFERROR(J12-K12,"") -> 1500
A13: 9 | B13: =HYPERLINK("Z:\MePork\000 綜合\020 報價合約\Quotation\2024\MS_Q1241_24_kp (C9644-24C Extension of Fitness Room at KBD Recreation & Sports Centre)\P1 - Payment\Payment records\"&A13&".PDF",A13) -> 9 | C13: 45701 | D13: INV13/2/2025 | F13: O-006 | G13: =IFERROR(VLOOKUP($F13,'Project Summary'!$B$9:$M$106,3,FALSE),"") -> FIRE EXTINGUISHER SAFETY CONSULTANT | H13: =IFERROR(VLOOKUP($F13,'Project Summary'!$B$9:$M$106,4,FALSE),"") -> 滅火筒安全顧問 | I13: =IFERROR(VLOOKUP($F13,'Project Summary'!$B$9:$M$106,5,FALSE),"") -> Safety | J13: =IFERROR(VLOOKUP($F13,'Project Summary'!$B$9:$M$106,7,FALSE),"") -> 272000 | K13: 16000 | L13: =IFERROR(J13-K13,"") -> 256000
A14: 10 | B14: =HYPERLINK("Z:\MePork\000 綜合\020 報價合約\Quotation\2024\MS_Q1241_24_kp (C9644-24C Extension of Fitness Room at KBD Recreation & Sports Centre)\P1 - Payment\Payment records\"&A14&".PDF",A14) -> 10 | C14: 45716 | F14: O-007 | G14: =IFERROR(VLOOKUP($F14,'Project Summary'!$B$9:$M$106,3,FALSE),"") -> MTR | H14: =IFERROR(VLOOKUP($F14,'Project Summary'!$B$9:$M$106,4,FALSE),"") -> 0 | I14: =IFERROR(VLOOKUP($F14,'Project Summary'!$B$9:$M$106,5,FALSE),"") -> CP Training | J14: =IFERROR(VLOOKUP($F14,'Project Summary'!$B$9:$M$106,7,FALSE),"") -> 2000 | K14: 1000 | L14: =IFERROR(J14-K14,"") -> 1000
A15: 11 | B15: =HYPERLINK("Z:\MePork\000 綜合\020 報價合約\Quotation\2024\MS_Q1241_24_kp (C9644-24C Extension of Fitness Room at KBD Recreation & Sports Centre)\P1 - Payment\Payment records\"&A15&".PDF",A15) -> 11 | C15: 45726 | D15: INV10/3/2025 | F15: O-006 | G15: =IFERROR(VLOOKUP($F15,'Project Summary'!$B$9:$M$106,3,FALSE),"") -> FIRE EXTINGUISHER SAFETY CONSULTANT | H15: =IFERROR(VLOOKUP($F15,'Project Summary'!$B$9:$M$106,4,FALSE),"") -> 滅火筒安全顧問 | I15: =IFERROR(VLOOKUP($F15,'Project Summary'!$B$9:$M$106,5,FALSE),"") -> Safety | J15: =IFERROR(VLOOKUP($F15,'Project Summary'!$B$9:$M$106,7,FALSE),"") -> 272000 | K15: 16000 | L15: =IFERROR(J15-K15,"") -> 256000
A16: 12 | B16: =HYPERLINK("Z:\MePork\000 綜合\020 報價合約\Quotation\2024\MS_Q1241_24_kp (C9644-24C Extension of Fitness Room at KBD Recreation & Sports Centre)\P1 - Payment\Payment records\"&A16&".PDF",A16) -> 12 | C16: 45735 | D16: DN18553-QL | F16: O-009 | G16: =IFERROR(VLOOKUP($F16,'Project Summary'!$B$9:$M$106,3,FALSE),"") -> UCMG | H16: =IFERROR(VLOOKUP($F16,'Project Summary'!$B$9:$M$106,4,FALSE),"") -> 聯康醫療 | I16: =IFERROR(VLOOKUP($F16,'Project Summary'!$B$9:$M$106,5,FALSE),"") -> Body Check | J16: =IFERROR(VLOOKUP($F16,'Project Summary'!$B$9:$M$106,7,FALSE),"") -> 1640 | K16: 540 | L16: =IFERROR(J16-K16,"") -> 1100
A17: 13 | B17: =HYPERLINK("Z:\MePork\000 綜合\020 報價合約\Quotation\2024\MS_Q1241_24_kp (C9644-24C Extension of Fitness Room at KBD Recreation & Sports Centre)\P1 - Payment\Payment records\"&A17&".PDF",A17) -> 13 | C17: 45748 | D17: INV 1/4/2025 | F17: O-006 | G17: =IFERROR(VLOOKUP($F17,'Project Summary'!$B$9:$M$106,3,FALSE),"") -> FIRE EXTINGUISHER SAFETY CONSULTANT | H17: =IFERROR(VLOOKUP($F17,'Project Summary'!$B$9:$M$106,4,FALSE),"") -> 滅火筒安全顧問 | I17: =IFERROR(VLOOKUP($F17,'Project Summary'!$B$9:$M$106,5,FALSE),"") -> Safety | J17: =IFERROR(VLOOKUP($F17,'Project Summary'!$B$9:$M$106,7,FALSE),"") -> 272000 | K17: 16000 | L17: =IFERROR(J17-K17,"") -> 256000
A18: 14 | B18: =HYPERLINK("Z:\MePork\000 綜合\020 報價合約\Quotation\2024\MS_Q1241_24_kp (C9644-24C Extension of Fitness Room at KBD Recreation & Sports Centre)\P1 - Payment\Payment records\"&A18&".PDF",A18) -> 14 | C18: 45763 | D18: DN18593-QL | F18: O-009 | G18: =IFERROR(VLOOKUP($F18,'Project Summary'!$B$9:$M$106,3,FALSE),"") -> UCMG | H18: =IFERROR(VLOOKUP($F18,'Project Summary'!$B$9:$M$106,4,FALSE),"") -> 聯康醫療 | I18: =IFERROR(VLOOKUP($F18,'Project Summary'!$B$9:$M$106,5,FALSE),"") -> Body Check | J18: =IFERROR(VLOOKUP($F18,'Project Summary'!$B$9:$M$106,7,FALSE),"") -> 1640 | K18: 270 | L18: =IFERROR(J18-K18,"") -> 1370
A19: 15 | B19: =HYPERLINK("Z:\MePork\000 綜合\020 報價合約\Quotation\2024\MS_Q1241_24_kp (C9644-24C Extension of Fitness Room at KBD Recreation & Sports Centre)\P1 - Payment\Payment records\"&A19&".PDF",A19) -> 15 | C19: 45749 | D19: INV 2/4/2025 | F19: O-006.1 | G19: =IFERROR(VLOOKUP($F19,'Project Summary'!$B$9:$M$106,3,FALSE),"") -> FIRE EXTINGUISHER SAFETY CONSULTANT | H19: =IFERROR(VLOOKUP($F19,'Project Summary'!$B$9:$M$106,4,FALSE),"") -> 滅火筒安全顧問 | I19: =IFERROR(VLOOKUP($F19,'Project Summary'!$B$9:$M$106,5,FALSE),"") -> Safety Review | J19: =IFERROR(VLOOKUP($F19,'Project Summary'!$B$9:$M$106,7,FALSE),"") -> 12000 | K19: 12000 | L19: =IFERROR(J19-K19,"") -> 0
A20: 16 | B20: =HYPERLINK("Z:\MePork\000 綜合\020 報價合約\Quotation\2024\MS_Q1241_24_kp (C9644-24C Extension of Fitness Room at KBD Recreation & Sports Centre)\P1 - Payment\Payment records\"&A20&".PDF",A20) -> 16 | C20: 45785 | D20: P24-28 | F20: SC-010 | G20: =IFERROR(VLOOKUP($F20,'Project Summary'!$B$9:$M$106,3,FALSE),"") -> CHIU MING COMPANY LIMITED | H20: =IFERROR(VLOOKUP($F20,'Project Summary'!$B$9:$M$106,4,FALSE),"") -> 照明工程有限公司 | I20: EL - IP-01 | J20: =IFERROR(VLOOKUP($F20,'Project Summary'!$B$9:$M$106,7,FALSE),"") -> 1100000 | K20: 126628 | L20: =IFERROR(J20-K20,"") -> 973372
A21: 17 | B21: =HYPERLINK("Z:\MePork\000 綜合\020 報價合約\Quotation\2024\MS_Q1241_24_kp (C9644-24C Extension of Fitness Room at KBD Recreation & Sports Centre)\P1 - Payment\Payment records\"&A21&".PDF",A21) -> 17 | C21: 45720 | D21: MB-202402b | F21: SC-008 | G21: =IFERROR(VLOOKUP($F21,'Project Summary'!$B$9:$M$106,3,FALSE),"") -> WAH MAN ENGINEERING COMPANY | H21: =IFERROR(VLOOKUP($F21,'Project Summary'!$B$9:$M$106,4,FALSE),"") -> 華文工程有限公司 | I21: =IFERROR(VLOOKUP($F21,'Project Summary'!$B$9:$M$106,5,FALSE),"") -> Design of Hoarding | J21: =IFERROR(VLOOKUP($F21,'Project Summary'!$B$9:$M$106,7,FALSE),"") -> 9500 | K21: 9500 | L21: =IFERROR(J21-K21,"") -> 0
A22: 18 | B22: =HYPERLINK("Z:\MePork\000 綜合\020 報價合約\Quotation\2024\MS_Q1241_24_kp (C9644-24C Extension of Fitness Room at KBD Recreation & Sports Centre)\P1 - Payment\Payment records\"&A22&".PDF",A22) -> 18 | C22: 45792 | D22: INV 15/5/2025 | F22: O-006 | G22: =IFERROR(VLOOKUP($F22,'Project Summary'!$B$9:$M$106,3,FALSE),"") -> FIRE EXTINGUISHER SAFETY CONSULTANT | H22: =IFERROR(VLOOKUP($F22,'Project Summary'!$B$9:$M$106,4,FALSE),"") -> 滅火筒安全顧問 | I22: =IFERROR(VLOOKUP($F22,'Project Summary'!$B$9:$M$106,5,FALSE),"") -> Safety | J22: =IFERROR(VLOOKUP($F22,'Project Summary'!$B$9:$M$106,7,FALSE),"") -> 272000 | K22: 16000 | L22: =IFERROR(J22-K22,"") -> 256000
A23: 19 | B23: =HYPERLINK("Z:\MePork\000 綜合\020 報價合約\Quotation\2024\MS_Q1241_24_kp (C9644-24C Extension of Fitness Room at KBD Recreation & Sports Centre)\P1 - Payment\Payment records\"&A23&".PDF",A23) -> 19 | C23: 45791 | F23: O-007 | G23: =IFERROR(VLOOKUP($F23,'Project Summary'!$B$9:$M$106,3,FALSE),"") -> MTR | H23: =IFERROR(VLOOKUP($F23,'Project Summary'!$B$9:$M$106,4,FALSE),"") -> 0 | I23: =IFERROR(VLOOKUP($F23,'Project Summary'!$B$9:$M$106,5,FALSE),"") -> CP Training | J23: =IFERROR(VLOOKUP($F23,'Project Summary'!$B$9:$M$106,7,FALSE),"") -> 2000 | K23: 500 | L23: =IFERROR(J23-K23,"") -> 1500
A24: 20 | B24: =HYPERLINK("Z:\MePork\000 綜合\020 報價合約\Quotation\2024\MS_Q1241_24_kp (C9644-24C Extension of Fitness Room at KBD Recreation & Sports Centre)\P1 - Payment\Payment records\"&A24&".PDF",A24) -> 20 | C24: 45818 | D24: DN3347788 | F24: O-012 | G24: =IFERROR(VLOOKUP($F24,'Project Summary'!$B$9:$M$106,3,FALSE),"") -> CONSTRUCTION INDUSTRY COUNCIL | H24: =IFERROR(VLOOKUP($F24,'Project Summary'!$B$9:$M$106,4,FALSE),"") -> 建造業議會 | I24: =IFERROR(VLOOKUP($F24,'Project Summary'!$B$9:$M$106,5,FALSE),"") -> Levies | J24: =IFERROR(VLOOKUP($F24,'Project Summary'!$B$9:$M$106,7,FALSE),"") -> 14006 | K24: 1493 | L24: =IFERROR(J24-K24,"") -> 12513
A25: 21 | B25: =HYPERLINK("Z:\MePork\000 綜合\020 報價合約\Quotation\2024\MS_Q1241_24_kp (C9644-24C Extension of Fitness Room at KBD Recreation & Sports Centre)\P1 - Payment\Payment records\"&A25&".PDF",A25) -> 21 | C25: 45835 | F25: SC-003 | G25: =IFERROR(VLOOKUP($F25,'Project Summary'!$B$9:$M$106,3,FALSE),"") -> WANG FAT CONSTRUCTION CO. | H25: =IFERROR(VLOOKUP($F25,'Project Summary'!$B$9:$M$106,4,FALSE),"") -> 宏發建築工程公司 | I25: =IFERROR(VLOOKUP($F25,'Project Summary'!$B$9:$M$106,5,FALSE),"") -> Builder's Works | J25: =IFERROR(VLOOKUP($F25,'Project Summary'!$B$9:$M$106,7,FALSE),"") -> 1900000 | K25: 190000 | L25: =IFERROR(J25-K25,"") -> 1710000
A26: 22 | B26: =HYPERLINK("Z:\MePork\000 綜合\020 報價合約\Quotation\2024\MS_Q1241_24_kp (C9644-24C Extension of Fitness Room at KBD Recreation & Sports Centre)\P1 - Payment\Payment records\"&A26&".PDF",A26) -> 22 | C26: 45835 | F26: SC-002 | G26: =IFERROR(VLOOKUP($F26,'Project Summary'!$B$9:$M$106,3,FALSE),"") -> CHASE ENGINEERING LIMITED | H26: =IFERROR(VLOOKUP($F26,'Project Summary'!$B$9:$M$106,4,FALSE),"") -> 大同工程有限公司 | I26: =IFERROR(VLOOKUP($F26,'Project Summary'!$B$9:$M$106,5,FALSE),"") -> Fire Services Installation | J26: =IFERROR(VLOOKUP($F26,'Project Summary'!$B$9:$M$106,7,FALSE),"") -> 800000 | K26: 235000 | L26: =IFERROR(J26-K26,"") -> 565000
A27: 23 | B27: =HYPERLINK("Z:\MePork\000 綜合\020 報價合約\Quotation\2024\MS_Q1241_24_kp (C9644-24C Extension of Fitness Room at KBD Recreation & Sports Centre)\P1 - Payment\Payment records\"&A27&".PDF",A27) -> 23 | C27: 45821 | D27: INV3//2025 | F27: O-006 | G27: =IFERROR(VLOOKUP($F27,'Project Summary'!$B$9:$M$106,3,FALSE),"") -> FIRE EXTINGUISHER SAFETY CONSULTANT | H27: =IFERROR(VLOOKUP($F27,'Project Summary'!$B$9:$M$106,4,FALSE),"") -> 滅火筒安全顧問 | I27: =IFERROR(VLOOKUP($F27,'Project Summary'!$B$9:$M$106,5,FALSE),"") -> Safety | J27: =IFERROR(VLOOKUP($F27,'Project Summary'!$B$9:$M$106,7,FALSE),"") -> 272000 | K27: 16000 | L27: =IFERROR(J27-K27,"") -> 256000
A28: 24 | B28: =HYPERLINK("Z:\MePork\000 綜合\020 報價合約\Quotation\2024\MS_Q1241_24_kp (C9644-24C Extension of Fitness Room at KBD Recreation & Sports Centre)\P1 - Payment\Payment records\"&A28&".PDF",A28) -> 24 | C28: 45809 | D28: P24-28 | F28: SC-010 | G28: =IFERROR(VLOOKUP($F28,'Project Summary'!$B$9:$M$106,3,FALSE),"") -> CHIU MING COMPANY LIMITED | H28: =IFERROR(VLOOKUP($F28,'Project Summary'!$B$9:$M$106,4,FALSE),"") -> 照明工程有限公司 | I28: EL - IP-02 | J28: =IFERROR(VLOOKUP($F28,'Project Summary'!$B$9:$M$106,7,FALSE),"") -> 1100000 | K28: 108500 | L28: =IFERROR(J28-K28,"") -> 991500
A29: 25 | B29: =HYPERLINK("Z:\MePork\000 綜合\020 報價合約\Quotation\2024\MS_Q1241_24_kp (C9644-24C Extension of Fitness Room at KBD Recreation & Sports Centre)\P1 - Payment\Payment records\"&A29&".PDF",A29) -> 25 | F29: O-013 | G29: =IFERROR(VLOOKUP($F29,'Project Summary'!$B$9:$M$106,3,FALSE),"") -> Miscellaneous | H29: =IFERROR(VLOOKUP($F29,'Project Summary'!$B$9:$M$106,4,FALSE),"") -> 0 | I29: =IFERROR(VLOOKUP($F29,'Project Summary'!$B$9:$M$106,5,FALSE),"") -> 0 | J29: =IFERROR(VLOOKUP($F29,'Project Summary'!$B$9:$M$106,7,FALSE),"") -> 12038.9 | K29: 1920 | L29: =IFERROR(J29-K29,"") -> 10118.9
A30: 26 | B30: =HYPERLINK("Z:\MePork\000 綜合\020 報價合約\Quotation\2024\MS_Q1241_24_kp (C9644-24C Extension of Fitness Room at KBD Recreation & Sports Centre)\P1 - Payment\Payment records\"&A30&".PDF",A30) -> 26 | C30: 45832 | D30: DN3581600 | F30: O-014 | G30: =IFERROR(VLOOKUP($F30,'Project Summary'!$B$9:$M$106,3,FALSE),"") -> PNEUMOCONIOSIS COMPENSATION FUND BOARD | H30: =IFERROR(VLOOKUP($F30,'Project Summary'!$B$9:$M$106,4,FALSE),"") -> 肺塵埃沉着病補償基金委員會 | I30: =IFERROR(VLOOKUP($F30,'Project Summary'!$B$9:$M$106,5,FALSE),"") -> Levies | J30: =IFERROR(VLOOKUP($F30,'Project Summary'!$B$9:$M$106,7,FALSE),"") -> 6279 | K30: 422 | L30: =IFERROR(J30-K30,"") -> 5857
A31: 27 | B31: =HYPERLINK("Z:\MePork\000 綜合\020 報價合約\Quotation\2024\MS_Q1241_24_kp (C9644-24C Extension of Fitness Room at KBD Recreation & Sports Centre)\P1 - Payment\Payment records\"&A31&".PDF",A31) -> 27 | C31: 45825 | D31: DN18711-QL | F31: O-009 | G31: =IFERROR(VLOOKUP($F31,'Project Summary'!$B$9:$M$106,3,FALSE),"") -> UCMG | H31: =IFERROR(VLOOKUP($F31,'Project Summary'!$B$9:$M$106,4,FALSE),"") -> 聯康醫療 | I31: =IFERROR(VLOOKUP($F31,'Project Summary'!$B$9:$M$106,5,FALSE),"") -> Body Check | J31: =IFERROR(VLOOKUP($F31,'Project Summary'!$B$9:$M$106,7,FALSE),"") -> 1640 | K31: 280 | L31: =IFERROR(J31-K31,"") -> 1360
A32: 28 | B32: =HYPERLINK("Z:\MePork\000 綜合\020 報價合約\Quotation\2024\MS_Q1241_24_kp (C9644-24C Extension of Fitness Room at KBD Recreation & Sports Centre)\P1 - Payment\Payment records\"&A32&".PDF",A32) -> 28 | C32: 45757 | D32: 64440 | F32: M-011.1 | G32: =IFERROR(VLOOKUP($F32,'Project Summary'!$B$9:$M$106,3,FALSE),"") -> SHUN SHING ELECTRICALS CO. LTD | H32: =IFERROR(VLOOKUP($F32,'Project Summary'!$B$9:$M$106,4,FALSE),"") -> 信成電器材料有限公司 | I32: =IFERROR(VLOOKUP($F32,'Project Summary'!$B$9:$M$106,5,FALSE),"") -> EL - Material | J32: =IFERROR(VLOOKUP($F32,'Project Summary'!$B$9:$M$106,7,FALSE),"") -> 32940 | K32: 32940 | L32: =IFERROR(J32-K32,"") -> 0
A33: 29 | B33: =HYPERLINK("Z:\MePork\000 綜合\020 報價合約\Quotation\2024\MS_Q1241_24_kp (C9644-24C Extension of Fitness Room at KBD Recreation & Sports Centre)\P1 - Payment\Payment records\"&A33&".PDF",A33) -> 29 | C33: 45753 | D33: 64331 | F33: M-011.2 | G33: =IFERROR(VLOOKUP($F33,'Project Summary'!$B$9:$M$106,3,FALSE),"") -> SHUN SHING ELECTRICALS CO. LTD | H33: =IFERROR(VLOOKUP($F33,'Project Summary'!$B$9:$M$106,4,FALSE),"") -> 信成電器材料有限公司 | I33: =IFERROR(VLOOKUP($F33,'Project Summary'!$B$9:$M$106,5,FALSE),"") -> EL - Material | J33: =IFERROR(VLOOKUP($F33,'Project Summary'!$B$9:$M$106,7,FALSE),"") -> 39055 | K33: 39055 | L33: =IFERROR(J33-K33,"") -> 0
A34: 30 | B34: =HYPERLINK("Z:\MePork\000 綜合\020 報價合約\Quotation\2024\MS_Q1241_24_kp (C9644-24C Extension of Fitness Room at KBD Recreation & Sports Centre)\P1 - Payment\Payment records\"&A34&".PDF",A34) -> 30 | C34: 45752 | D34: 64187 | F34: M-011.3 | G34: =IFERROR(VLOOKUP($F34,'Project Summary'!$B$9:$M$106,3,FALSE),"") -> SHUN SHING ELECTRICALS CO. LTD | H34: =IFERROR(VLOOKUP($F34,'Project Summary'!$B$9:$M$106,4,FALSE),"") -> 信成電器材料有限公司 | I34: =IFERROR(VLOOKUP($F34,'Project Summary'!$B$9:$M$106,5,FALSE),"") -> EL - Material | J34: =IFERROR(VLOOKUP($F34,'Project Summary'!$B$9:$M$106,7,FALSE),"") -> 21960 | K34: 21960 | L34: =IFERROR(J34-K34,"") -> 0
A35: 31 | B35: =HYPERLINK("Z:\MePork\000 綜合\020 報價合約\Quotation\2024\MS_Q1241_24_kp (C9644-24C Extension of Fitness Room at KBD Recreation & Sports Centre)\P1 - Payment\Payment records\"&A35&".PDF",A35) -> 31 | C35: 45775 | D35: 64286 | F35: M-011.4 | G35: =IFERROR(VLOOKUP($F35,'Project Summary'!$B$9:$M$106,3,FALSE),"") -> SHUN SHING ELECTRICALS CO. LTD | H35: =IFERROR(VLOOKUP($F35,'Project Summary'!$B$9:$M$106,4,FALSE),"") -> 信成電器材料有限公司 | I35: =IFERROR(VLOOKUP($F35,'Project Summary'!$B$9:$M$106,5,FALSE),"") -> EL - Material | J35: =IFERROR(VLOOKUP($F35,'Project Summary'!$B$9:$M$106,7,FALSE),"") -> 19740 | K35: 19740 | L35: =IFERROR(J35-K35,"") -> 0
A36: 32 | B36: =HYPERLINK("Z:\MePork\000 綜合\020 報價合約\Quotation\2024\MS_Q1241_24_kp (C9644-24C Extension of Fitness Room at KBD Recreation & Sports Centre)\P1 - Payment\Payment records\"&A36&".PDF",A36) -> 32 | C36: 45773 | D36: 64272 | F36: M-011.5 | G36: =IFERROR(VLOOKUP($F36,'Project Summary'!$B$9:$M$106,3,FALSE),"") -> SHUN SHING ELECTRICALS CO. LTD | H36: =IFERROR(VLOOKUP($F36,'Project Summary'!$B$9:$M$106,4,FALSE),"") -> 信成電器材料有限公司 | I36: =IFERROR(VLOOKUP($F36,'Project Summary'!$B$9:$M$106,5,FALSE),"") -> EL - Material | J36: =IFERROR(VLOOKUP($F36,'Project Summary'!$B$9:$M$106,7,FALSE),"") -> 2080 | K36: 2080 | L36: =IFERROR(J36-K36,"") -> 0
A37: 33 | B37: =HYPERLINK("Z:\MePork\000 綜合\020 報價合約\Quotation\2024\MS_Q1241_24_kp (C9644-24C Extension of Fitness Room at KBD Recreation & Sports Centre)\P1 - Payment\Payment records\"&A37&".PDF",A37) -> 33 | C37: 45852 | D37: INV14/7/2025 | F37: O-006 | G37: =IFERROR(VLOOKUP($F37,'Project Summary'!$B$9:$M$106,3,FALSE),"") -> FIRE EXTINGUISHER SAFETY CONSULTANT | H37: =IFERROR(VLOOKUP($F37,'Project Summary'!$B$9:$M$106,4,FALSE),"") -> 滅火筒安全顧問 | I37: =IFERROR(VLOOKUP($F37,'Project Summary'!$B$9:$M$106,5,FALSE),"") -> Safety | J37: =IFERROR(VLOOKUP($F37,'Project Summary'!$B$9:$M$106,7,FALSE),"") -> 272000 | K37: 16000 | L37: =IFERROR(J37-K37,"") -> 256000
A38: 34 | B38: =HYPERLINK("Z:\MePork\000 綜合\020 報價合約\Quotation\2024\MS_Q1241_24_kp (C9644-24C Extension of Fitness Room at KBD Recreation & Sports Centre)\P1 - Payment\Payment records\"&A38&".PDF",A38) -> 34 | C38: 45855 | D38: 12025082 | F38: SC-004A | G38: =IFERROR(VLOOKUP($F38,'Project Summary'!$B$9:$M$106,3,FALSE),"") -> YING PAK ENGINEERING COMPANY | H38: =IFERROR(VLOOKUP($F38,'Project Summary'!$B$9:$M$106,4,FALSE),"") -> 盈泊工程公司 | I38: MVAC Installation - IP-02 (VO) | J38: =IFERROR(VLOOKUP($F38,'Project Summary'!$B$9:$M$106,7,FALSE),"") -> 83000 | K38: 83000 | L38: =IFERROR(J38-K38,"") -> 0
A39: 35 | B39: =HYPERLINK("Z:\MePork\000 綜合\020 報價合約\Quotation\2024\MS_Q1241_24_kp (C9644-24C Extension of Fitness Room at KBD Recreation & Sports Centre)\P1 - Payment\Payment records\"&A39&".PDF",A39) -> 35 | C39: 45826 | D39: IVA01106-25 | F39: M-015 | G39: =IFERROR(VLOOKUP($F39,'Project Summary'!$B$9:$M$106,3,FALSE),"") -> ALCO LIGHTING (H.K.) LTD | H39: =IFERROR(VLOOKUP($F39,'Project Summary'!$B$9:$M$106,4,FALSE),"") -> 0 | I39: =IFERROR(VLOOKUP($F39,'Project Summary'!$B$9:$M$106,5,FALSE),"") -> Light fitting | J39: =IFERROR(VLOOKUP($F39,'Project Summary'!$B$9:$M$106,7,FALSE),"") -> 174600 | K39: 174600 | L39: =IFERROR(J39-K39,"") -> 0
A40: 36 | B40: =HYPERLINK("Z:\MePork\000 綜合\020 報價合約\Quotation\2024\MS_Q1241_24_kp (C9644-24C Extension of Fitness Room at KBD Recreation & Sports Centre)\P1 - Payment\Payment records\"&A40&".PDF",A40) -> 36 | C40: 45854 | D40: 12025064 | F40: SC-004 | G40: =IFERROR(VLOOKUP($F40,'Project Summary'!$B$9:$M$106,3,FALSE),"") -> YING PAK ENGINEERING COMPANY | H40: =IFERROR(VLOOKUP($F40,'Project Summary'!$B$9:$M$106,4,FALSE),"") -> 盈泊工程公司 | I40: MVAC Installation - IP-03 | J40: =IFERROR(VLOOKUP($F40,'Project Summary'!$B$9:$M$106,7,FALSE),"") -> 800000 | K40: 138000 | L40: =IFERROR(J40-K40,"") -> 662000
...

Sheet Project Summary
A1: 美博工程服務有限公司
A2: MS_Q1241_24_kp (MTR C9644-24C Extension of Fitness Room at KBD Recreation & Sports Centre)
A4: 總承建商(MC): | B4: Mepork Engineering Services Limited | I4: 承建金額: | J4: =Summary!B18 -> 7400000
I5: (a) | L5: $1,720,000.00 Contingency
I6: (A) Sub-total: | J6: =SUM(J4:J4) -> 7400000
A8: Item | B8: Sub-contractors' No. | C8: Quotation Copy | D8: Sub-contractors' Name | E8: Company Name (in Chinese) | F8: Nature of S/C Works | G8: Contract Charge | H8: Contract Sum | I8: VO | J8: Revised Contract Sum | K8: Remark | L8: 合約會簽表 (10萬以上) | M8: Contract | N8: 定標會議紀錄 (100萬以上) | O8: 報價已簽名 | P8: 正本已存檔 | Q8: OA
A9: 1 | B9: O-001 | C9: =HYPERLINK("Z:\MePork\000 綜合\020 報價合約\Quotation\2024\MS_Q1241_24_kp (C9644-24C Extension of Fitness Room at KBD Recreation & Sports Centre)\P1 - Payment\Quotation Records\"&B9&".PDF",B9) -> O-001 | D9: REALIFE INSURANCE BROKERS LTD. | E9: 恒傑保險業務有限公司 | F9: Insurance - EC | H9: 44360 | J9: =H9+I9 -> 44360 | L9: - | M9: OK | N9: OK | P9: OK | Q9: 45640 | R9: =J9/Summary!B18 -> 0.0059945946
A10: 1A | B10: O-001.1 | C10: =HYPERLINK("Z:\MePork\000 綜合\020 報價合約\Quotation\2024\MS_Q1241_24_kp (C9644-24C Extension of Fitness Room at KBD Recreation & Sports Centre)\P1 - Payment\Quotation Records\"&B10&".PDF",B10) -> O-001.1 | D10: REALIFE INSURANCE BROKERS LTD. | E10: 恒傑保險業務有限公司 | F10: Insurance - EC Extension | H10: 12366.35 | J10: =H10+I10 -> 12366.35 | Q10: 46049
A11: 2 | B11: SC-002 | C11: =HYPERLINK("Z:\MePork\000 綜合\020 報價合約\Quotation\2024\MS_Q1241_24_kp (C9644-24C Extension of Fitness Room at KBD Recreation & Sports Centre)\P1 - Payment\Quotation Records\"&B11&".PDF",B11) -> SC-002 | D11: CHASE ENGINEERING LIMITED | E11: 大同工程有限公司 | F11: Fire Services Installation | H11: 800000 | J11: =H11+I11 -> 800000 | L11: OK | M11: OK | N11: - | O11: OK | P11: Quotation saved | Q11: 45647
A12: 2A | B12: SC-002A | C12: =HYPERLINK("Z:\MePork\000 綜合\020 報價合約\Quotation\2024\MS_Q1241_24_kp (C9644-24C Extension of Fitness Room at KBD Recreation & Sports Centre)\P1 - Payment\Quotation Records\"&B12&".PDF",B12) -> SC-002A | D12: CHASE ENGINEERING LIMITED | E12: 大同工程有限公司 | F12: Supply Smoke Detector | H12: 12000 | J12: =H12+I12 -> 12000 | K12: 扣宏發 | Q12: 45978
A13: 3 | B13: SC-003 | C13: =HYPERLINK("Z:\MePork\000 綜合\020 報價合約\Quotation\2024\MS_Q1241_24_kp (C9644-24C Extension of Fitness Room at KBD Recreation & Sports Centre)\P1 - Payment\Quotation Records\"&B13&".PDF",B13) -> SC-003 | D13: WANG FAT CONSTRUCTION CO. | E13: 宏發建築工程公司 | F13: Builder's Works | H13: 1900000 | J13: =H13+I13 -> 1900000 | L13: OK | M13: OK | O13: OK | P13: Quotation saved | Q13: 45647
A14: 3A | B14: SC-003A | C14: =HYPERLINK("Z:\MePork\000 綜合\020 報價合約\Quotation\2024\MS_Q1241_24_kp (C9644-24C Extension of Fitness Room at KBD Recreation & Sports Centre)\P1 - Payment\Quotation Records\"&B14&".PDF",B14) -> SC-003A | D14: WANG FAT CONSTRUCTION CO. | E14: 宏發建築工程公司 | F14: Q167/21 搭架比EMSD驗收燈柱 | H14: 15000 | J14: =H14+I14 -> 15000 | Q14: 45828
A15: 3B | B15: SC-003B | D15: WANG FAT CONSTRUCTION CO. | E15: 宏發建築工程公司 | F15: Tony 帳款 | H15: =350700+796500-500000 -> 647200 | J15: =H15+I15 -> 647200
A16: 4 | B16: SC-004 | C16: =HYPERLINK("Z:\MePork\000 綜合\020 報價合約\Quotation\2024\MS_Q1241_24_kp (C9644-24C Extension of Fitness Room at KBD Recreation & Sports Centre)\P1 - Payment\Quotation Records\"&B16&".PDF",B16) -> SC-004 | D16: YING PAK ENGINEERING COMPANY | E16: 盈泊工程公司 | F16: MVAC Installation | H16: 800000 | J16: =H16+I16 -> 800000 | L16: OK | M16: OK | N16: - | O16: OK | P16: Quotation saved | Q16: 45647
A17: 5A | B17: SC-004A | C17: =HYPERLINK("Z:\MePork\000 綜合\020 報價合約\Quotation\2024\MS_Q1241_24_kp (C9644-24C Extension of Fitness Room at KBD Recreation & Sports Centre)\P1 - Payment\Quotation Records\"&B17&".PDF",B17) -> SC-004A | D17: YING PAK ENGINEERING COMPANY | E17: 盈泊工程公司 | F17: 代買冷氣機 | H17: 83000 | J17: =H17+I17 -> 83000 | Q17: 45861
A18: 5 | B18: O-005 | C18: =HYPERLINK("Z:\MePork\000 綜合\020 報價合約\Quotation\2024\MS_Q1241_24_kp (C9644-24C Extension of Fitness Room at KBD Recreation & Sports Centre)\P1 - Payment\Quotation Records\"&B18&".PDF",B18) -> O-005 | D18: Environmental Protection Department | E18: 環境保護署 | F18: Waste Dispoal | H18: =15000+4562.5+540+500+2940+520+3180 -> 27242.5 | J18: =H18+I18 -> 27242.5 | K18: $15,000 Deposit | L18: - | M18: - | N18: - | O18: - | P18: - | Q18: -
A19: 6 | B19: O-006 | C19: =HYPERLINK("Z:\MePork\000 綜合\020 報價合約\Quotation\2024\MS_Q1241_24_kp (C9644-24C Extension of Fitness Room at KBD Recreation & Sports Centre)\P1 - Payment\Quotation Records\"&B19&".PDF",B19) -> O-006 | D19: FIRE EXTINGUISHER SAFETY CONSULTANT | E19: 滅火筒安全顧問 | F19: Safety | H19: =16000*17 -> 272000 | J19: =H19+I19 -> 272000 | K19: $16,000 / month | L19: OK | M19: - | N19: - | O19: OK | P19: OK | Q19: 45646
A20: 6.2 | B20: O-006.2 | C20: =HYPERLINK("Z:\MePork\000 綜合\020 報價合約\Quotation\2024\MS_Q1241_24_kp (C9644-24C Extension of Fitness Room at KBD Recreation & Sports Centre)\P1 - Payment\Quotation Records\"&B20&".PDF",B20) -> O-006.2 | D20: FIRE EXTINGUISHER SAFETY CONSULTANT | E20: 滅火筒安全顧問 | F20: Safety 延期 | H20: 112000 | J20: =H20+I20 -> 112000 | Q20: 46175
A21: 6.1 | B21: O-006.1 | C21: =HYPERLINK("Z:\MePork\000 綜合\020 報價合約\Quotation\2024\MS_Q1241_24_kp (C9644-24C Extension of Fitness Room at KBD Recreation & Sports Centre)\P1 - Payment\Quotation Records\"&B21&".PDF",B21) -> O-006.1 | D21: FIRE EXTINGUISHER SAFETY CONSULTANT | E21: 滅火筒安全顧問 | F21: Safety Review | H21: 12000 | J21: =H21+I21 -> 12000 | L21: - | M21: - | N21: - | O21: OK | P21: OK | Q21: 45775
A22: 7 | B22: O-007 | C22: =HYPERLINK("Z:\MePork\000 綜合\020 報價合約\Quotation\2024\MS_Q1241_24_kp (C9644-24C Extension of Fitness Room at KBD Recreation & Sports Centre)\P1 - Payment\Quotation Records\"&B22&".PDF",B22) -> O-007 | D22: MTR | F22: CP Training | H22: =500+1000+500 -> 2000 | J22: =H22+I22 -> 2000 | L22: - | M22: - | N22: - | O22: - | P22: - | Q22: -
A23: 8 | B23: SC-008 | C23: =HYPERLINK("Z:\MePork\000 綜合\020 報價合約\Quotation\2024\MS_Q1241_24_kp (C9644-24C Extension of Fitness Room at KBD Recreation & Sports Centre)\P1 - Payment\Quotation Records\"&B23&".PDF",B23) -> SC-008 | D23: WAH MAN ENGINEERING COMPANY | E23: 華文工程有限公司 | F23: Design of Hoarding | H23: 9500 | J23: =H23+I23 -> 9500
A24: 8.1 | B24: SC-008.1 | C24: =HYPERLINK("Z:\MePork\000 綜合\020 報價合約\Quotation\2024\MS_Q1241_24_kp (C9644-24C Extension of Fitness Room at KBD Recreation & Sports Centre)\P1 - Payment\Quotation Records\"&B24&".PDF",B24) -> SC-008.1 | D24: WAH MAN ENGINEERING COMPANY | E24: 華文工程有限公司 | F24: Structural Engineering Consultancy | H24: 6000 | J24: =H24+I24 -> 6000 | Q24: 45873
A25: 9 | B25: O-009 | C25: =HYPERLINK("Z:\MePork\000 綜合\020 報價合約\Quotation\2024\MS_Q1241_24_kp (C9644-24C Extension of Fitness Room at KBD Recreation & Sports Centre)\P1 - Payment\Quotation Records\"&B25&".PDF",B25) -> O-009 | D25: UCMG | E25: 聯康醫療 | F25: Body Check | H25: =270*2+270+280+270+280 -> 1640 | J25: =H25+I25 -> 1640
A26: 10 | B26: SC-010 | C26: =HYPERLINK("Z:\MePork\000 綜合\020 報價合約\Quotation\2024\MS_Q1241_24_kp (C9644-24C Extension of Fitness Room at KBD Recreation & Sports Centre)\P1 - Payment\Quotation Records\"&B26&".PDF",B26) -> SC-010 | D26: CHIU MING COMPANY LIMITED | E26: 照明工程有限公司 | F26: EL | H26: 1100000 | J26: =H26+I26 -> 1100000
A27: 10.1 | B27: SC-010.1 | C27: =HYPERLINK("Z:\MePork\000 綜合\020 報價合約\Quotation\2024\MS_Q1241_24_kp (C9644-24C Extension of Fitness Room at KBD Recreation & Sports Centre)\P1 - Payment\Quotation Records\"&B27&".PDF",B27) -> SC-010.1 | D27: CHIU MING COMPANY LIMITED | E27: 照明工程有限公司 | F27: EL - VO-01 (EI-01) | H27: 112880 | J27: =H27+I27 -> 112880 | Q27: 45669
A28: 11 | B28: M-011.1 | C28: =HYPERLINK("Z:\MePork\000 綜合\020 報價合約\Quotation\2024\MS_Q1241_24_kp (C9644-24C Extension of Fitness Room at KBD Recreation & Sports Centre)\P1 - Payment\Quotation Records\"&B28&".PDF",B28) -> M-011.1 | D28: SHUN SHING ELECTRICALS CO. LTD | E28: 信成電器材料有限公司 | F28: EL - Material | H28: =9*3660 -> 32940 | J28: =H28+I28 -> 32940 | Q28: 45861
A29: 11 | B29: M-011.2 | C29: =HYPERLINK("Z:\MePork\000 綜合\020 報價合約\Quotation\2024\MS_Q1241_24_kp (C9644-24C Extension of Fitness Room at KBD Recreation & Sports Centre)\P1 - Payment\Quotation Records\"&B29&".PDF",B29) -> M-011.2 | D29: SHUN SHING ELECTRICALS CO. LTD | E29: 信成電器材料有限公司 | F29: EL - Material | H29: =7*4440+7975 -> 39055 | J29: =H29+I29 -> 39055 | Q29: 45861
A30: 11 | B30: M-011.3 | C30: =HYPERLINK("Z:\MePork\000 綜合\020 報價合約\Quotation\2024\MS_Q1241_24_kp (C9644-24C Extension of Fitness Room at KBD Recreation & Sports Centre)\P1 - Payment\Quotation Records\"&B30&".PDF",B30) -> M-011.3 | D30: SHUN SHING ELECTRICALS CO. LTD | E30: 信成電器材料有限公司 | F30: EL - Material | H30: =6*3660 -> 21960 | J30: =H30+I30 -> 21960 | Q30: 45861
A31: 11 | B31: M-011.4 | C31: =HYPERLINK("Z:\MePork\000 綜合\020 報價合約\Quotation\2024\MS_Q1241_24_kp (C9644-24C Extension of Fitness Room at KBD Recreation & Sports Centre)\P1 - Payment\Quotation Records\"&B31&".PDF",B31) -> M-011.4 | D31: SHUN SHING ELECTRICALS CO. LTD | E31: 信成電器材料有限公司 | F31: EL - Material | H31: =7*2820 -> 19740 | J31: =H31+I31 -> 19740 | Q31: 45861
A32: 11 | B32: M-011.5 | C32: =HYPERLINK("Z:\MePork\000 綜合\020 報價合約\Quotation\2024\MS_Q1241_24_kp (C9644-24C Extension of Fitness Room at KBD Recreation & Sports Centre)\P1 - Payment\Quotation Records\"&B32&".PDF",B32) -> M-011.5 | D32: SHUN SHING ELECTRICALS CO. LTD | E32: 信成電器材料有限公司 | F32: EL - Material | H32: =2080 -> 2080 | J32: =H32+I32 -> 2080 | Q32: 45861
A33: 11 | B33: M-011.6 | C33: =HYPERLINK("Z:\MePork\000 綜合\020 報價合約\Quotation\2024\MS_Q1241_24_kp (C9644-24C Extension of Fitness Room at KBD Recreation & Sports Centre)\P1 - Payment\Quotation Records\"&B33&".PDF",B33) -> M-011.6 | D33: SHUN SHING ELECTRICALS CO. LTD | E33: 信成電器材料有限公司 | F33: EL - Material | H33: 5400 | J33: =H33+I33 -> 5400 | Q33: 45861
A34: 11 | B34: M-011.7 | C34: =HYPERLINK("Z:\MePork\000 綜合\020 報價合約\Quotation\2024\MS_Q1241_24_kp (C9644-24C Extension of Fitness Room at KBD Recreation & Sports Centre)\P1 - Payment\Quotation Records\"&B34&".PDF",B34) -> M-011.7 | D34: SHUN SHING ELECTRICALS CO. LTD | E34: 信成電器材料有限公司 | F34: EL - Material | H34: 1353 | J34: =H34+I34 -> 1353 | Q34: 45861
A35: 11 | B35: M-011.8 | C35: =HYPERLINK("Z:\MePork\000 綜合\020 報價合約\Quotation\2024\MS_Q1241_24_kp (C9644-24C Extension of Fitness Room at KBD Recreation & Sports Centre)\P1 - Payment\Quotation Records\"&B35&".PDF",B35) -> M-011.8 | D35: SHUN SHING ELECTRICALS CO. LTD | E35: 信成電器材料有限公司 | F35: EL - Material | H35: 1988.3 | J35: =H35+I35 -> 1988.3 | Q35: 45861
A36: 11 | B36: M-011.9 | C36: =HYPERLINK("Z:\MePork\000 綜合\020 報價合約\Quotation\2024\MS_Q1241_24_kp (C9644-24C Extension of Fitness Room at KBD Recreation & Sports Centre)\P1 - Payment\Quotation Records\"&B36&".PDF",B36) -> M-011.9 | D36: SHUN SHING ELECTRICALS CO. LTD | E36: 信成電器材料有限公司 | F36: EL - Material | H36: =16*115.1+20*14+50*4+2*36 -> 2393.6 | J36: =H36+I36 -> 2393.6 | Q36: 45861
A37: 11 | B37: M-011.10 | C37: =HYPERLINK("Z:\MePork\000 綜合\020 報價合約\Quotation\2024\MS_Q1241_24_kp (C9644-24C Extension of Fitness Room at KBD Recreation & Sports Centre)\P1 - Payment\Quotation Records\"&B37&".PDF",B37) -> M-011.10 | D37: SHUN SHING ELECTRICALS CO. LTD | E37: 信成電器材料有限公司 | F37: EL - Material | H37: =80*28+100*2.5+200+200+40*28+10*37+5*67+100*1.5+50*136.9+11*64.8+7*439.2 -> 15497.2 | J37: =H37+I37 -> 15497.2 | Q37: 45861
A38: 11 | B38: M-011.11 | C38: =HYPERLINK("Z:\MePork\000 綜合\020 報價合約\Quotation\2024\MS_Q1241_24_kp (C9644-24C Extension of Fitness Room at KBD Recreation & Sports Centre)\P1 - Payment\Quotation Records\"&B38&".PDF",B38) -> M-011.11 | D38: SHUN SHING ELECTRICALS CO. LTD | E38: 信成電器材料有限公司 | F38: EL - Material | H38: =80*28+20*36+200*2.5+200+200*1.5+50*1.5+50*1.5+50*3+30*3+50*28+2*375+100*7 -> 7200 | J38: =H38+I38 -> 7200 | Q38: 45861
A39: 11 | B39: M-011.12 | C39: =HYPERLINK("Z:\MePork\000 綜合\020 報價合約\Quotation\2024\MS_Q1241_24_kp (C9644-24C Extension of Fitness Room at KBD Recreation & Sports Centre)\P1 - Payment\Quotation Records\"&B39&".PDF",B39) -> M-011.12 | D39: SHUN SHING ELECTRICALS CO. LTD | E39: 信成電器材料有限公司 | F39: EL - Material | H39: =3*2040 -> 6120 | J39: =H39+I39 -> 6120 | Q39: 45861
A40: 11 | B40: M-011.13 | C40: =HYPERLINK("Z:\MePork\000 綜合\020 報價合約\Quotation\2024\MS_Q1241_24_kp (C9644-24C Extension of Fitness Room at KBD Recreation & Sports Centre)\P1 - Payment\Quotation Records\"&B40&".PDF",B40) -> M-011.13 | D40: SHUN SHING ELECTRICALS CO. LTD | E40: 信成電器材料有限公司 | F40: EL - Material | H40: 900 | J40: =H40+I40 -> 900 | Q40: 45861
A41: 11 | B41: M-011.14 | C41: =HYPERLINK("Z:\MePork\000 綜合\020 報價合約\Quotation\2024\MS_Q1241_24_kp (C9644-24C Extension of Fitness Room at KBD Recreation & Sports Centre)\P1 - Payment\Quotation Records\"&B41&".PDF",B41) -> M-011.14 | D41: SHUN SHING ELECTRICALS CO. LTD | E41: 信成電器材料有限公司 | F41: EL - Material | H41: =50*8+20*13+50*18+50*8+50*13+100*3.3+100*2+3*36+6*20+20*115.1+20*27+50*4 -> 6410 | J41: =H41+I41 -> 6410 | Q41: 45861
A42: 11 | B42: M-011.15 | C42: =HYPERLINK("Z:\MePork\000 綜合\020 報價合約\Quotation\2024\MS_Q1241_24_kp (C9644-24C Extension of Fitness Room at KBD Recreation & Sports Centre)\P1 - Payment\Quotation Records\"&B42&".PDF",B42) -> M-011.15 | D42: SHUN SHING ELECTRICALS CO. LTD | E42: 信成電器材料有限公司 | F42: EL - Material | H42: =60*136.9+480+85+2*15+20*3+10*4 -> 8909 | J42: =H42+I42 -> 8909 | Q42: 45861
...
